[2022-12-10 03:45:29,487] INFO [basedcount_bot.py.check_mail:43] Received message from is_fake_Account, suggestion: rewrite the whole bot
[2022-12-10 04:17:48,828] CRITICAL [basedcount_bot.py.wrapper:23] Serious Exception
Traceback (most recent call last):
  File "/mnt/secondary-ssd/Programming/Pycharm/basedcount_bot/basedcount_bot.py", line 36, in check_mail
    async for message in reddit_instance.inbox.unread(limit=None):  # Message
  File "/mnt/secondary-ssd/Programming/Pycharm/basedcount_bot/venv/lib/python3.10/site-packages/asyncpraw/models/listing/generator.py", line 63, in __anext__
    await self._next_batch()
  File "/mnt/secondary-ssd/Programming/Pycharm/basedcount_bot/venv/lib/python3.10/site-packages/asyncpraw/models/listing/generator.py", line 94, in _next_batch
    raise StopAsyncIteration()
StopAsyncIteration

During handling of the above exception, another exception occurred:

Traceback (most recent call last):
  File "/mnt/secondary-ssd/Programming/Pycharm/basedcount_bot/basedcount_bot.py", line 19, in wrapper
    await func(reddit_instance)
  File "/mnt/secondary-ssd/Programming/Pycharm/basedcount_bot/basedcount_bot.py", line 82, in check_mail
    await message.mark_read()
TypeError: 'StopAsyncIteration' object is not callable
[2022-12-10 04:18:16,861] CRITICAL [basedcount_bot.py.wrapper:23] Serious Exception
Traceback (most recent call last):
  File "/mnt/secondary-ssd/Programming/Pycharm/basedcount_bot/basedcount_bot.py", line 36, in check_mail
    async for message in reddit_instance.inbox.unread(limit=None):  # Message
  File "/mnt/secondary-ssd/Programming/Pycharm/basedcount_bot/venv/lib/python3.10/site-packages/asyncpraw/models/listing/generator.py", line 63, in __anext__
    await self._next_batch()
  File "/mnt/secondary-ssd/Programming/Pycharm/basedcount_bot/venv/lib/python3.10/site-packages/asyncpraw/models/listing/generator.py", line 94, in _next_batch
    raise StopAsyncIteration()
StopAsyncIteration

During handling of the above exception, another exception occurred:

Traceback (most recent call last):
  File "/mnt/secondary-ssd/Programming/Pycharm/basedcount_bot/basedcount_bot.py", line 19, in wrapper
    await func(reddit_instance)
  File "/mnt/secondary-ssd/Programming/Pycharm/basedcount_bot/basedcount_bot.py", line 82, in check_mail
    await message.mark_read()
TypeError: 'StopAsyncIteration' object is not callable
[2022-12-10 04:19:04,172] CRITICAL [basedcount_bot.py.wrapper:23] Serious Exception
Traceback (most recent call last):
  File "/mnt/secondary-ssd/Programming/Pycharm/basedcount_bot/basedcount_bot.py", line 36, in check_mail
    async for message in reddit_instance.inbox.unread(limit=None):  # Message
  File "/mnt/secondary-ssd/Programming/Pycharm/basedcount_bot/venv/lib/python3.10/site-packages/asyncpraw/models/listing/generator.py", line 63, in __anext__
    await self._next_batch()
  File "/mnt/secondary-ssd/Programming/Pycharm/basedcount_bot/venv/lib/python3.10/site-packages/asyncpraw/models/listing/generator.py", line 94, in _next_batch
    raise StopAsyncIteration()
StopAsyncIteration

During handling of the above exception, another exception occurred:

Traceback (most recent call last):
  File "/mnt/secondary-ssd/Programming/Pycharm/basedcount_bot/basedcount_bot.py", line 19, in wrapper
    await func(reddit_instance)
  File "/mnt/secondary-ssd/Programming/Pycharm/basedcount_bot/basedcount_bot.py", line 82, in check_mail
    await message.mark_read()
TypeError: 'StopAsyncIteration' object is not callable
[2022-12-10 04:19:14,833] CRITICAL [basedcount_bot.py.wrapper:23] Serious Exception
Traceback (most recent call last):
  File "/mnt/secondary-ssd/Programming/Pycharm/basedcount_bot/basedcount_bot.py", line 36, in check_mail
    async for message in reddit_instance.inbox.unread(limit=None):  # Message
  File "/mnt/secondary-ssd/Programming/Pycharm/basedcount_bot/venv/lib/python3.10/site-packages/asyncpraw/models/listing/generator.py", line 63, in __anext__
    await self._next_batch()
  File "/mnt/secondary-ssd/Programming/Pycharm/basedcount_bot/venv/lib/python3.10/site-packages/asyncpraw/models/listing/generator.py", line 94, in _next_batch
    raise StopAsyncIteration()
StopAsyncIteration

During handling of the above exception, another exception occurred:

Traceback (most recent call last):
  File "/mnt/secondary-ssd/Programming/Pycharm/basedcount_bot/basedcount_bot.py", line 19, in wrapper
    await func(reddit_instance)
  File "/mnt/secondary-ssd/Programming/Pycharm/basedcount_bot/basedcount_bot.py", line 82, in check_mail
    await message.mark_read()
TypeError: 'StopAsyncIteration' object is not callable
[2022-12-10 04:20:56,241] INFO [basedcount_bot.py.check_mail:43] Received message from is_fake_Account, /mybasedcount: /mybasedcount
[2022-12-10 04:27:28,086] INFO [basedcount_bot.py.check_mail:43] Received message from is_fake_Account, /mybasedcount: /mybasedcount
[2022-12-10 04:28:11,405] CRITICAL [basedcount_bot.py.wrapper:23] Serious Exception
Traceback (most recent call last):
  File "/mnt/secondary-ssd/Programming/Pycharm/basedcount_bot/basedcount_bot.py", line 36, in check_mail
    async for message in reddit_instance.inbox.unread(limit=None):  # Message
  File "/mnt/secondary-ssd/Programming/Pycharm/basedcount_bot/venv/lib/python3.10/site-packages/asyncpraw/models/listing/generator.py", line 63, in __anext__
    await self._next_batch()
  File "/mnt/secondary-ssd/Programming/Pycharm/basedcount_bot/venv/lib/python3.10/site-packages/asyncpraw/models/listing/generator.py", line 94, in _next_batch
    raise StopAsyncIteration()
StopAsyncIteration

During handling of the above exception, another exception occurred:

Traceback (most recent call last):
  File "/mnt/secondary-ssd/Programming/Pycharm/basedcount_bot/basedcount_bot.py", line 19, in wrapper
    await func(reddit_instance)
  File "/mnt/secondary-ssd/Programming/Pycharm/basedcount_bot/basedcount_bot.py", line 82, in check_mail
    await message.mark_read()
TypeError: 'StopAsyncIteration' object is not callable
[2022-12-10 04:29:14,251] INFO [basedcount_bot.py.check_mail:43] Received message from is_fake_Account, /mybasedcount: /mybasedcount
[2022-12-10 04:31:03,405] CRITICAL [basedcount_bot.py.wrapper:23] Serious Exception
Traceback (most recent call last):
  File "/mnt/secondary-ssd/Programming/Pycharm/basedcount_bot/basedcount_bot.py", line 19, in wrapper
    await func(reddit_instance)
  File "/mnt/secondary-ssd/Programming/Pycharm/basedcount_bot/basedcount_bot.py", line 69, in check_mail
    my_based_count = await get_based_count(user_name=message.author.name, is_me=True)
  File "/mnt/secondary-ssd/Programming/Pycharm/basedcount_bot/commands.py", line 91, in get_based_count
    profile = await data_based.find_one({"name": user_name})
TypeError: '_asyncio.FutureIter' object is not callable
[2022-12-10 04:33:42,583] INFO [basedcount_bot.py.check_mail:43] Received message from is_fake_Account, /mybasedcount: /mybasedcount
[2022-12-10 04:40:36,610] INFO [basedcount_bot.py.check_mail:43] Received message from is_fake_Account, /mybasedcount: /mybasedcount
[2022-12-10 04:40:59,213] ERROR [basedcount_bot.py.wrapper:21] AsyncPrawcoreException
Traceback (most recent call last):
  File "/mnt/secondary-ssd/Programming/Pycharm/basedcount_bot/venv/lib/python3.10/site-packages/asyncprawcore/requestor.py", line 64, in request
    return await self._http.request(
  File "/mnt/secondary-ssd/Programming/Pycharm/basedcount_bot/venv/lib/python3.10/site-packages/aiohttp/client.py", line 560, in _request
    await resp.start(conn)
  File "/mnt/secondary-ssd/Programming/Pycharm/basedcount_bot/venv/lib/python3.10/site-packages/aiohttp/client_reqrep.py", line 894, in start
    with self._timer:
  File "/mnt/secondary-ssd/Programming/Pycharm/basedcount_bot/venv/lib/python3.10/site-packages/aiohttp/helpers.py", line 720, in __exit__
    raise asyncio.TimeoutError from None
asyncio.exceptions.TimeoutError

During handling of the above exception, another exception occurred:

Traceback (most recent call last):
  File "/mnt/secondary-ssd/Programming/Pycharm/basedcount_bot/basedcount_bot.py", line 19, in wrapper
    await func(reddit_instance)
  File "/mnt/secondary-ssd/Programming/Pycharm/basedcount_bot/basedcount_bot.py", line 88, in read_comments
    print(await reddit_instance.user.me())
  File "/mnt/secondary-ssd/Programming/Pycharm/basedcount_bot/venv/lib/python3.10/site-packages/asyncpraw/util/deprecate_args.py", line 51, in wrapped
    return await _wrapper(*args, **kwargs)
  File "/mnt/secondary-ssd/Programming/Pycharm/basedcount_bot/venv/lib/python3.10/site-packages/asyncpraw/models/user.py", line 169, in me
    user_data = await self._reddit.get(API_PATH["me"])
  File "/mnt/secondary-ssd/Programming/Pycharm/basedcount_bot/venv/lib/python3.10/site-packages/asyncpraw/util/deprecate_args.py", line 51, in wrapped
    return await _wrapper(*args, **kwargs)
  File "/mnt/secondary-ssd/Programming/Pycharm/basedcount_bot/venv/lib/python3.10/site-packages/asyncpraw/reddit.py", line 707, in get
    return await self._objectify_request(method="GET", params=params, path=path)
  File "/mnt/secondary-ssd/Programming/Pycharm/basedcount_bot/venv/lib/python3.10/site-packages/asyncpraw/reddit.py", line 815, in _objectify_request
    await self.request(
  File "/mnt/secondary-ssd/Programming/Pycharm/basedcount_bot/venv/lib/python3.10/site-packages/asyncpraw/util/deprecate_args.py", line 51, in wrapped
    return await _wrapper(*args, **kwargs)
  File "/mnt/secondary-ssd/Programming/Pycharm/basedcount_bot/venv/lib/python3.10/site-packages/asyncpraw/reddit.py", line 1032, in request
    return await self._core.request(
  File "/mnt/secondary-ssd/Programming/Pycharm/basedcount_bot/venv/lib/python3.10/site-packages/asyncprawcore/sessions.py", line 370, in request
    return await self._request_with_retries(
  File "/mnt/secondary-ssd/Programming/Pycharm/basedcount_bot/venv/lib/python3.10/site-packages/asyncprawcore/sessions.py", line 270, in _request_with_retries
    response, saved_exception = await self._make_request(
  File "/mnt/secondary-ssd/Programming/Pycharm/basedcount_bot/venv/lib/python3.10/site-packages/asyncprawcore/sessions.py", line 187, in _make_request
    response = await self._rate_limiter.call(
  File "/mnt/secondary-ssd/Programming/Pycharm/basedcount_bot/venv/lib/python3.10/site-packages/asyncprawcore/rate_limit.py", line 35, in call
    response = await request_function(*args, **kwargs)
  File "/mnt/secondary-ssd/Programming/Pycharm/basedcount_bot/venv/lib/python3.10/site-packages/asyncprawcore/requestor.py", line 68, in request
    raise RequestException(exc, args, kwargs)
asyncprawcore.exceptions.RequestException: error with request
[2022-12-10 04:41:00,287] CRITICAL [basedcount_bot.py.wrapper:23] Serious Exception
Traceback (most recent call last):
  File "/mnt/secondary-ssd/Programming/Pycharm/basedcount_bot/basedcount_bot.py", line 19, in wrapper
    await func(reddit_instance)
  File "/mnt/secondary-ssd/Programming/Pycharm/basedcount_bot/basedcount_bot.py", line 69, in check_mail
    my_based_count = await get_based_count(user_name=message.author.name, is_me=True)
  File "/mnt/secondary-ssd/Programming/Pycharm/basedcount_bot/commands.py", line 91, in get_based_count
    profile = await data_based.find_one({"name": user_name})
TypeError: '_asyncio.FutureIter' object is not callable
[2022-12-10 04:42:32,762] INFO [basedcount_bot.py.check_mail:43] Received message from is_fake_Account, /mybasedcount: /mybasedcount
[2022-12-10 04:42:36,998] CRITICAL [basedcount_bot.py.wrapper:23] Serious Exception
Traceback (most recent call last):
  File "/mnt/secondary-ssd/Programming/Pycharm/basedcount_bot/basedcount_bot.py", line 19, in wrapper
    await func(reddit_instance)
  File "/mnt/secondary-ssd/Programming/Pycharm/basedcount_bot/basedcount_bot.py", line 69, in check_mail
    my_based_count = await get_based_count(user_name=message.author.name, is_me=True)
  File "/mnt/secondary-ssd/Programming/Pycharm/basedcount_bot/commands.py", line 91, in get_based_count
    d = await data_based
TypeError: object MotorCollection can't be used in 'await' expression
[2022-12-10 04:44:48,019] INFO [basedcount_bot.py.check_mail:43] Received message from is_fake_Account, /mybasedcount: /mybasedcount
[2022-12-10 04:48:59,607] INFO [basedcount_bot.py.check_mail:43] Received message from is_fake_Account, /mybasedcount: /mybasedcount
[2022-12-10 04:52:12,645] INFO [basedcount_bot.py.check_mail:43] Received message from is_fake_Account, /mybasedcount: /mybasedcount
[2022-12-10 14:56:04,073] INFO [basedcount_bot.py.check_mail:43] Received message from is_fake_Account, the_names_savage: /basedcount the_names_savage
[2022-12-10 14:56:38,123] CRITICAL [basedcount_bot.py.wrapper:23] Serious Exception
Traceback (most recent call last):
  File "/mnt/secondary-ssd/Programming/Pycharm/basedcount_bot/basedcount_bot.py", line 19, in wrapper
    await func(reddit_instance)
  File "/mnt/secondary-ssd/Programming/Pycharm/basedcount_bot/basedcount_bot.py", line 75, in check_mail
    user_based_count = await get_based_count(user_name=user_name, is_me=False)
  File "/mnt/secondary-ssd/Programming/Pycharm/basedcount_bot/commands.py", line 90, in get_based_count
    count = profile.get("count", 0)
AttributeError: 'NoneType' object has no attribute 'get'
[2022-12-10 14:58:36,522] INFO [basedcount_bot.py.check_mail:43] Received message from is_fake_Account, the_names_savage: /basedcount the_names_savage
[2022-12-10 15:02:42,221] INFO [basedcount_bot.py.check_mail:43] Received message from is_fake_Account, the_names_savage: /basedcount the_names_savage
[2022-12-10 15:03:39,223] ERROR [basedcount_bot.py.wrapper:21] AsyncPrawcoreException
Traceback (most recent call last):
  File "/mnt/secondary-ssd/Programming/Pycharm/basedcount_bot/venv/lib/python3.10/site-packages/asyncprawcore/requestor.py", line 64, in request
    return await self._http.request(
  File "/mnt/secondary-ssd/Programming/Pycharm/basedcount_bot/venv/lib/python3.10/site-packages/aiohttp/client.py", line 560, in _request
    await resp.start(conn)
  File "/mnt/secondary-ssd/Programming/Pycharm/basedcount_bot/venv/lib/python3.10/site-packages/aiohttp/client_reqrep.py", line 894, in start
    with self._timer:
  File "/mnt/secondary-ssd/Programming/Pycharm/basedcount_bot/venv/lib/python3.10/site-packages/aiohttp/helpers.py", line 720, in __exit__
    raise asyncio.TimeoutError from None
asyncio.exceptions.TimeoutError

During handling of the above exception, another exception occurred:

Traceback (most recent call last):
  File "/mnt/secondary-ssd/Programming/Pycharm/basedcount_bot/basedcount_bot.py", line 19, in wrapper
    await func(reddit_instance)
  File "/mnt/secondary-ssd/Programming/Pycharm/basedcount_bot/basedcount_bot.py", line 89, in read_comments
    print(await reddit_instance.user.me())
  File "/mnt/secondary-ssd/Programming/Pycharm/basedcount_bot/venv/lib/python3.10/site-packages/asyncpraw/util/deprecate_args.py", line 51, in wrapped
    return await _wrapper(*args, **kwargs)
  File "/mnt/secondary-ssd/Programming/Pycharm/basedcount_bot/venv/lib/python3.10/site-packages/asyncpraw/models/user.py", line 169, in me
    user_data = await self._reddit.get(API_PATH["me"])
  File "/mnt/secondary-ssd/Programming/Pycharm/basedcount_bot/venv/lib/python3.10/site-packages/asyncpraw/util/deprecate_args.py", line 51, in wrapped
    return await _wrapper(*args, **kwargs)
  File "/mnt/secondary-ssd/Programming/Pycharm/basedcount_bot/venv/lib/python3.10/site-packages/asyncpraw/reddit.py", line 707, in get
    return await self._objectify_request(method="GET", params=params, path=path)
  File "/mnt/secondary-ssd/Programming/Pycharm/basedcount_bot/venv/lib/python3.10/site-packages/asyncpraw/reddit.py", line 815, in _objectify_request
    await self.request(
  File "/mnt/secondary-ssd/Programming/Pycharm/basedcount_bot/venv/lib/python3.10/site-packages/asyncpraw/util/deprecate_args.py", line 51, in wrapped
    return await _wrapper(*args, **kwargs)
  File "/mnt/secondary-ssd/Programming/Pycharm/basedcount_bot/venv/lib/python3.10/site-packages/asyncpraw/reddit.py", line 1032, in request
    return await self._core.request(
  File "/mnt/secondary-ssd/Programming/Pycharm/basedcount_bot/venv/lib/python3.10/site-packages/asyncprawcore/sessions.py", line 370, in request
    return await self._request_with_retries(
  File "/mnt/secondary-ssd/Programming/Pycharm/basedcount_bot/venv/lib/python3.10/site-packages/asyncprawcore/sessions.py", line 270, in _request_with_retries
    response, saved_exception = await self._make_request(
  File "/mnt/secondary-ssd/Programming/Pycharm/basedcount_bot/venv/lib/python3.10/site-packages/asyncprawcore/sessions.py", line 187, in _make_request
    response = await self._rate_limiter.call(
  File "/mnt/secondary-ssd/Programming/Pycharm/basedcount_bot/venv/lib/python3.10/site-packages/asyncprawcore/rate_limit.py", line 35, in call
    response = await request_function(*args, **kwargs)
  File "/mnt/secondary-ssd/Programming/Pycharm/basedcount_bot/venv/lib/python3.10/site-packages/asyncprawcore/requestor.py", line 68, in request
    raise RequestException(exc, args, kwargs)
asyncprawcore.exceptions.RequestException: error with request
[2022-12-10 15:37:13,922] INFO [basedcount_bot.py.check_mail:43] Received message from is_fake_Account, the_names_savage: /basedcount the_names_savage
[2022-12-10 15:38:24,158] INFO [basedcount_bot.py.check_mail:43] Received message from is_fake_Account, the_names_savage: /basedcount the_names_savage
[2022-12-10 15:39:05,740] INFO [basedcount_bot.py.check_mail:43] Received message from is_fake_Account, the_names_savage: /basedcount the_names_savage
[2022-12-10 15:39:47,435] INFO [basedcount_bot.py.check_mail:43] Received message from is_fake_Account, the_names_savage: /basedcount the_names_savage
[2022-12-10 15:42:54,412] INFO [basedcount_bot.py.check_mail:43] Received message from is_fake_Account, the_names_savage: /basedcount the_names_savage
[2022-12-10 15:52:07,135] INFO [basedcount_bot.py.check_mail:43] Received message from is_fake_Account, /mybasedcount: /mybasedcount
[2022-12-10 15:53:42,891] INFO [basedcount_bot.py.check_mail:43] Received message from is_fake_Account, /mybasedcount: /mybasedcount
[2022-12-10 15:57:57,015] INFO [basedcount_bot.py.check_mail:43] Received message from is_fake_Account, /mybasedcount: /mybasedcount
[2022-12-10 22:55:38,697] INFO [basedcount_bot.py.check_mail:46] Received message from is_fake_Account, sdfsd: /basedcount basedcount_bot
[2022-12-10 23:22:31,080] INFO [basedcount_bot.py.check_mail:46] Received message from is_fake_Account, dsf: /basedcount dhskfjdfh
[2022-12-11 01:16:21,203] INFO [basedcount_bot.py.cheating_report:38] Sending Cheating Report to admins.
[2022-12-11 01:16:22,179] INFO [basedcount_bot.py.check_mail:59] Received message from is_fake_Account, dsf: /basedcount dhskfjdfh
[2022-12-11 01:44:21,960] INFO [basedcount_bot.py.cheating_report:38] Sending Cheating Report to admins.
[2022-12-11 01:44:41,037] INFO [basedcount_bot.py.cheating_report:38] Sending Cheating Report to admins.
[2022-12-11 01:44:47,171] INFO [basedcount_bot.py.cheating_report:38] Sending Cheating Report to admins.
[2022-12-11 01:45:08,581] INFO [basedcount_bot.py.cheating_report:38] Sending Cheating Report to admins.
[2022-12-11 01:46:00,234] INFO [basedcount_bot.py.cheating_report:38] Sending Cheating Report to admins.
[2022-12-11 01:46:01,274] CRITICAL [basedcount_bot.py.wrapper:24] Serious Exception
Traceback (most recent call last):
  File "/mnt/secondary-ssd/Programming/Pycharm/basedcount_bot/basedcount_bot.py", line 52, in check_mail
    async for message in reddit_instance.inbox.unread(limit=None):  # Message
  File "/mnt/secondary-ssd/Programming/Pycharm/basedcount_bot/venv/lib/python3.10/site-packages/asyncpraw/models/listing/generator.py", line 63, in __anext__
    await self._next_batch()
  File "/mnt/secondary-ssd/Programming/Pycharm/basedcount_bot/venv/lib/python3.10/site-packages/asyncpraw/models/listing/generator.py", line 94, in _next_batch
    raise StopAsyncIteration()
StopAsyncIteration

During handling of the above exception, another exception occurred:

Traceback (most recent call last):
  File "/mnt/secondary-ssd/Programming/Pycharm/basedcount_bot/basedcount_bot.py", line 20, in wrapper
    await func(reddit_instance)
  File "/mnt/secondary-ssd/Programming/Pycharm/basedcount_bot/basedcount_bot.py", line 97, in check_mail
    await message.mark_read()
AttributeError: type object 'StopAsyncIteration' has no attribute 'mark_read'
[2022-12-11 01:47:06,655] INFO [basedcount_bot.py.cheating_report:38] Sending Cheating Report to admins.
[2022-12-11 01:47:10,778] INFO [basedcount_bot.py.check_mail:59] Received message from is_fake_Account, /info: /info
[2022-12-11 01:48:01,512] INFO [basedcount_bot.py.cheating_report:38] Sending Cheating Report to admins.
[2022-12-11 01:48:32,970] INFO [basedcount_bot.py.cheating_report:38] Sending Cheating Report to admins.
[2022-12-11 01:49:05,127] INFO [basedcount_bot.py.check_mail:59] Received message from is_fake_Account, /info: /info
[2022-12-11 01:50:02,236] INFO [basedcount_bot.py.cheating_report:38] Sending Cheating Report to admins.
[2022-12-11 02:14:43,701] INFO [basedcount_bot.py.cheating_report:38] Sending Cheating Report to admins.
[2022-12-11 02:15:30,965] INFO [basedcount_bot.py.check_mail:59] Received message from is_fake_Account, /mybasedcount: /mybasedcount
[2022-12-11 02:15:32,197] CRITICAL [basedcount_bot.py.wrapper:24] Serious Exception
Traceback (most recent call last):
  File "/mnt/secondary-ssd/Programming/Pycharm/basedcount_bot/basedcount_bot.py", line 20, in wrapper
    await func(reddit_instance)
  File "/mnt/secondary-ssd/Programming/Pycharm/basedcount_bot/basedcount_bot.py", line 83, in check_mail
    my_based_count = await get_based_count(user_name=message.author.name, is_me=True)
  File "/mnt/secondary-ssd/Programming/Pycharm/basedcount_bot/bot_commands.py", line 22, in get_based_count
    user = User.from_data(profile)
  File "/mnt/secondary-ssd/Programming/Pycharm/basedcount_bot/models/user.py", line 66, in from_data
    user_id=user_dict["id"],
KeyError: 'id'
[2022-12-11 02:15:59,858] INFO [basedcount_bot.py.cheating_report:38] Sending Cheating Report to admins.
[2022-12-11 02:16:00,839] INFO [basedcount_bot.py.check_mail:59] Received message from is_fake_Account, /mybasedcount: /mybasedcount
[2022-12-11 02:16:22,566] INFO [basedcount_bot.py.cheating_report:38] Sending Cheating Report to admins.
[2022-12-11 02:16:23,460] INFO [basedcount_bot.py.check_mail:59] Received message from is_fake_Account, /mybasedcount: /mybasedcount
[2022-12-11 02:16:50,808] CRITICAL [basedcount_bot.py.wrapper:24] Serious Exception
Traceback (most recent call last):
  File "/mnt/secondary-ssd/Programming/Pycharm/basedcount_bot/basedcount_bot.py", line 20, in wrapper
    await func(reddit_instance)
  File "/mnt/secondary-ssd/Programming/Pycharm/basedcount_bot/basedcount_bot.py", line 83, in check_mail
    my_based_count = await get_based_count(user_name=message.author.name, is_me=True)
  File "/mnt/secondary-ssd/Programming/Pycharm/basedcount_bot/bot_commands.py", line 22, in get_based_count
    user = User.from_data(profile)
  File "/mnt/secondary-ssd/Programming/Pycharm/basedcount_bot/models/user.py", line 71, in from_data
    sappy_values=user_dict["sappy"],
KeyError: 'sappy'
[2022-12-11 02:17:04,213] INFO [basedcount_bot.py.cheating_report:38] Sending Cheating Report to admins.
[2022-12-11 02:17:05,159] INFO [basedcount_bot.py.check_mail:59] Received message from is_fake_Account, /mybasedcount: /mybasedcount
[2022-12-11 02:17:33,718] CRITICAL [basedcount_bot.py.wrapper:24] Serious Exception
Traceback (most recent call last):
  File "/mnt/secondary-ssd/Programming/Pycharm/basedcount_bot/basedcount_bot.py", line 20, in wrapper
    await func(reddit_instance)
  File "/mnt/secondary-ssd/Programming/Pycharm/basedcount_bot/basedcount_bot.py", line 83, in check_mail
    my_based_count = await get_based_count(user_name=message.author.name, is_me=True)
  File "/mnt/secondary-ssd/Programming/Pycharm/basedcount_bot/bot_commands.py", line 22, in get_based_count
    user = User.from_data(profile)
  File "/mnt/secondary-ssd/Programming/Pycharm/basedcount_bot/models/user.py", line 71, in from_data
    sappy_values=user_dict["sappy"],
KeyError: 'sappy'
[2022-12-11 02:17:42,382] INFO [basedcount_bot.py.cheating_report:38] Sending Cheating Report to admins.
[2022-12-11 02:17:43,288] INFO [basedcount_bot.py.check_mail:59] Received message from is_fake_Account, /mybasedcount: /mybasedcount
[2022-12-11 02:18:33,306] CRITICAL [basedcount_bot.py.wrapper:24] Serious Exception
Traceback (most recent call last):
  File "/mnt/secondary-ssd/Programming/Pycharm/basedcount_bot/basedcount_bot.py", line 20, in wrapper
    await func(reddit_instance)
  File "/mnt/secondary-ssd/Programming/Pycharm/basedcount_bot/basedcount_bot.py", line 83, in check_mail
    my_based_count = await get_based_count(user_name=message.author.name, is_me=True)
  File "/mnt/secondary-ssd/Programming/Pycharm/basedcount_bot/bot_commands.py", line 25, in get_based_count
    f"Rank: {await user.get_rank_name()}.\n\n"
  File "/mnt/secondary-ssd/Programming/Pycharm/basedcount_bot/models/user.py", line 85, in get_rank_name
    return await rank_name(self.based_count, self.username)
  File "/mnt/secondary-ssd/Programming/Pycharm/basedcount_bot/models/ranks.py", line 49, in rank_name
    raise ValueError("No ranks for the given based count.")
ValueError: No ranks for the given based count.
[2022-12-11 02:19:02,050] INFO [basedcount_bot.py.cheating_report:38] Sending Cheating Report to admins.
[2022-12-11 02:19:03,063] INFO [basedcount_bot.py.check_mail:59] Received message from is_fake_Account, /mybasedcount: /mybasedcount
[2022-12-11 02:19:23,633] INFO [basedcount_bot.py.cheating_report:38] Sending Cheating Report to admins.
[2022-12-11 02:19:24,514] INFO [basedcount_bot.py.check_mail:59] Received message from is_fake_Account, /mybasedcount: /mybasedcount
[2022-12-11 02:21:51,527] INFO [basedcount_bot.py.check_mail:59] Received message from is_fake_Account, /basedcount: /basedcount presidentjoe
[2022-12-11 02:29:46,767] INFO [basedcount_bot.py.check_mail:59] Received message from is_fake_Account, /basedcount voidblade459: /basedcount voidblade459
[2022-12-11 02:34:36,095] INFO [basedcount_bot.py.cheating_report:38] Sending Cheating Report to admins.
[2022-12-11 02:35:02,565] INFO [basedcount_bot.py.check_mail:59] Received message from is_fake_Account, /basedcount voidblade459: /basedcount voidblade459
[2022-12-11 17:22:04,360] INFO [basedcount_bot.py.cheating_report:38] Sending Cheating Report to admins.
[2022-12-11 17:58:43,903] INFO [basedcount_bot.py.read_comments:98] Logged into XUIDChecker Account.
[2022-12-11 17:59:24,769] INFO [basedcount_bot.py.check_mail:47] Received message from is_fake_Account, /basedcount voidblade459: /basedcount voidblade459
[2022-12-11 17:59:56,987] INFO [basedcount_bot.py.check_mail:47] Received message from is_fake_Account, /basedcount voidblade459: /basedcount u/voidblade459
[2022-12-11 18:00:25,856] INFO [basedcount_bot.py.read_comments:98] Logged into XUIDChecker Account.
[2022-12-11 18:00:25,984] CRITICAL [basedcount_bot.py.wrapper:25] Serious Exception
Traceback (most recent call last):
  File "/mnt/secondary-ssd/Programming/Pycharm/basedcount_bot/basedcount_bot.py", line 40, in check_mail
    async for message in reddit_instance.inbox.unread(limit=None):  # Message
  File "/mnt/secondary-ssd/Programming/Pycharm/basedcount_bot/venv/lib/python3.10/site-packages/asyncpraw/models/listing/generator.py", line 63, in __anext__
    await self._next_batch()
  File "/mnt/secondary-ssd/Programming/Pycharm/basedcount_bot/venv/lib/python3.10/site-packages/asyncpraw/models/listing/generator.py", line 94, in _next_batch
    raise StopAsyncIteration()
StopAsyncIteration

During handling of the above exception, another exception occurred:

Traceback (most recent call last):
  File "/mnt/secondary-ssd/Programming/Pycharm/basedcount_bot/basedcount_bot.py", line 21, in wrapper
    await func(reddit_instance)
  File "/mnt/secondary-ssd/Programming/Pycharm/basedcount_bot/basedcount_bot.py", line 85, in check_mail
    await message.mark_read()
AttributeError: type object 'StopAsyncIteration' has no attribute 'mark_read'
[2022-12-11 18:00:39,474] INFO [basedcount_bot.py.read_comments:98] Logged into XUIDChecker Account.
[2022-12-11 18:01:00,895] INFO [basedcount_bot.py.read_comments:98] Logged into XUIDChecker Account.
[2022-12-11 18:15:59,468] INFO [basedcount_bot.py.read_comments:98] Logged into XUIDChecker Account.
[2022-12-11 18:16:13,104] INFO [basedcount_bot.py.check_mail:47] Received message from is_fake_Account, /basedcount u/voidblade459: /basedcount u/voidblade459
[2022-12-11 18:19:43,895] INFO [basedcount_bot.py.read_comments:98] Logged into XUIDChecker Account.
[2022-12-11 18:20:19,611] INFO [basedcount_bot.py.check_mail:47] Received message from is_fake_Account, /basedcount presidentjoe: /basedcount u/presidentjoe
[2022-12-11 18:20:46,835] INFO [basedcount_bot.py.check_mail:47] Received message from is_fake_Account, /basedcount presidentjoe: /basedcount presidentjoe
[2022-12-11 18:34:10,662] INFO [basedcount_bot.py.read_comments:98] Logged into XUIDChecker Account.
[2022-12-11 18:34:36,147] INFO [basedcount_bot.py.check_mail:47] Received message from is_fake_Account, /mostbased: /mostbased
[2022-12-11 18:34:36,282] CRITICAL [basedcount_bot.py.wrapper:25] Serious Exception
Traceback (most recent call last):
  File "/mnt/secondary-ssd/Programming/Pycharm/basedcount_bot/basedcount_bot.py", line 21, in wrapper
    await func(reddit_instance)
  File "/mnt/secondary-ssd/Programming/Pycharm/basedcount_bot/basedcount_bot.py", line 83, in check_mail
    await most_based()
  File "/mnt/secondary-ssd/Programming/Pycharm/basedcount_bot/bot_commands.py", line 17, in most_based
    top_ten = await data_based.find().sort("count", -1).limit(10)
TypeError: object MotorCursor can't be used in 'await' expression
[2022-12-11 18:39:28,538] INFO [basedcount_bot.py.check_mail:47] Received message from is_fake_Account, /mostbased: /mostbased
[2022-12-11 18:39:28,659] CRITICAL [basedcount_bot.py.wrapper:26] Serious Exception
Traceback (most recent call last):
  File "/mnt/secondary-ssd/Programming/Pycharm/basedcount_bot/basedcount_bot.py", line 22, in wrapper
    await func(reddit_instance)
  File "/mnt/secondary-ssd/Programming/Pycharm/basedcount_bot/basedcount_bot.py", line 83, in check_mail
    await most_based()
  File "/mnt/secondary-ssd/Programming/Pycharm/basedcount_bot/bot_commands.py", line 17, in most_based
    top_ten = await data_based.find().sort("count", -1).limit(10)
TypeError: object MotorCursor can't be used in 'await' expression
[2022-12-11 18:39:28,661] INFO [basedcount_bot.py.read_comments:98] Logged into XUIDChecker Account.
[2022-12-11 18:39:28,795] INFO [basedcount_bot.py.check_mail:47] Received message from is_fake_Account, /mostbased: /mostbased
[2022-12-11 18:39:28,798] CRITICAL [basedcount_bot.py.wrapper:26] Serious Exception
Traceback (most recent call last):
  File "/mnt/secondary-ssd/Programming/Pycharm/basedcount_bot/basedcount_bot.py", line 22, in wrapper
    await func(reddit_instance)
  File "/mnt/secondary-ssd/Programming/Pycharm/basedcount_bot/basedcount_bot.py", line 83, in check_mail
    await most_based()
  File "/mnt/secondary-ssd/Programming/Pycharm/basedcount_bot/bot_commands.py", line 17, in most_based
    top_ten = await data_based.find().sort("count", -1).limit(10)
TypeError: object MotorCursor can't be used in 'await' expression
[2022-12-11 18:39:28,921] INFO [basedcount_bot.py.check_mail:47] Received message from is_fake_Account, /mostbased: /mostbased
[2022-12-11 18:39:28,924] CRITICAL [basedcount_bot.py.wrapper:26] Serious Exception
Traceback (most recent call last):
  File "/mnt/secondary-ssd/Programming/Pycharm/basedcount_bot/basedcount_bot.py", line 22, in wrapper
    await func(reddit_instance)
  File "/mnt/secondary-ssd/Programming/Pycharm/basedcount_bot/basedcount_bot.py", line 83, in check_mail
    await most_based()
  File "/mnt/secondary-ssd/Programming/Pycharm/basedcount_bot/bot_commands.py", line 17, in most_based
    top_ten = await data_based.find().sort("count", -1).limit(10)
TypeError: object MotorCursor can't be used in 'await' expression
[2022-12-11 18:39:29,039] INFO [basedcount_bot.py.check_mail:47] Received message from is_fake_Account, /mostbased: /mostbased
[2022-12-11 18:39:29,041] CRITICAL [basedcount_bot.py.wrapper:26] Serious Exception
Traceback (most recent call last):
  File "/mnt/secondary-ssd/Programming/Pycharm/basedcount_bot/basedcount_bot.py", line 22, in wrapper
    await func(reddit_instance)
  File "/mnt/secondary-ssd/Programming/Pycharm/basedcount_bot/basedcount_bot.py", line 83, in check_mail
    await most_based()
  File "/mnt/secondary-ssd/Programming/Pycharm/basedcount_bot/bot_commands.py", line 17, in most_based
    top_ten = await data_based.find().sort("count", -1).limit(10)
TypeError: object MotorCursor can't be used in 'await' expression
[2022-12-11 18:39:29,136] INFO [basedcount_bot.py.check_mail:47] Received message from is_fake_Account, /mostbased: /mostbased
[2022-12-11 18:39:29,140] CRITICAL [basedcount_bot.py.wrapper:26] Serious Exception
Traceback (most recent call last):
  File "/mnt/secondary-ssd/Programming/Pycharm/basedcount_bot/basedcount_bot.py", line 22, in wrapper
    await func(reddit_instance)
  File "/mnt/secondary-ssd/Programming/Pycharm/basedcount_bot/basedcount_bot.py", line 83, in check_mail
    await most_based()
  File "/mnt/secondary-ssd/Programming/Pycharm/basedcount_bot/bot_commands.py", line 17, in most_based
    top_ten = await data_based.find().sort("count", -1).limit(10)
TypeError: object MotorCursor can't be used in 'await' expression
[2022-12-11 18:39:29,262] INFO [basedcount_bot.py.check_mail:47] Received message from is_fake_Account, /mostbased: /mostbased
[2022-12-11 18:39:29,264] CRITICAL [basedcount_bot.py.wrapper:26] Serious Exception
Traceback (most recent call last):
  File "/mnt/secondary-ssd/Programming/Pycharm/basedcount_bot/basedcount_bot.py", line 22, in wrapper
    await func(reddit_instance)
  File "/mnt/secondary-ssd/Programming/Pycharm/basedcount_bot/basedcount_bot.py", line 83, in check_mail
    await most_based()
  File "/mnt/secondary-ssd/Programming/Pycharm/basedcount_bot/bot_commands.py", line 17, in most_based
    top_ten = await data_based.find().sort("count", -1).limit(10)
TypeError: object MotorCursor can't be used in 'await' expression
[2022-12-11 18:39:29,395] INFO [basedcount_bot.py.check_mail:47] Received message from is_fake_Account, /mostbased: /mostbased
[2022-12-11 18:39:29,397] CRITICAL [basedcount_bot.py.wrapper:26] Serious Exception
Traceback (most recent call last):
  File "/mnt/secondary-ssd/Programming/Pycharm/basedcount_bot/basedcount_bot.py", line 22, in wrapper
    await func(reddit_instance)
  File "/mnt/secondary-ssd/Programming/Pycharm/basedcount_bot/basedcount_bot.py", line 83, in check_mail
    await most_based()
  File "/mnt/secondary-ssd/Programming/Pycharm/basedcount_bot/bot_commands.py", line 17, in most_based
    top_ten = await data_based.find().sort("count", -1).limit(10)
TypeError: object MotorCursor can't be used in 'await' expression
[2022-12-11 18:39:29,510] INFO [basedcount_bot.py.check_mail:47] Received message from is_fake_Account, /mostbased: /mostbased
[2022-12-11 18:39:29,513] CRITICAL [basedcount_bot.py.wrapper:26] Serious Exception
Traceback (most recent call last):
  File "/mnt/secondary-ssd/Programming/Pycharm/basedcount_bot/basedcount_bot.py", line 22, in wrapper
    await func(reddit_instance)
  File "/mnt/secondary-ssd/Programming/Pycharm/basedcount_bot/basedcount_bot.py", line 83, in check_mail
    await most_based()
  File "/mnt/secondary-ssd/Programming/Pycharm/basedcount_bot/bot_commands.py", line 17, in most_based
    top_ten = await data_based.find().sort("count", -1).limit(10)
TypeError: object MotorCursor can't be used in 'await' expression
[2022-12-11 18:39:29,624] INFO [basedcount_bot.py.check_mail:47] Received message from is_fake_Account, /mostbased: /mostbased
[2022-12-11 18:39:29,627] CRITICAL [basedcount_bot.py.wrapper:26] Serious Exception
Traceback (most recent call last):
  File "/mnt/secondary-ssd/Programming/Pycharm/basedcount_bot/basedcount_bot.py", line 22, in wrapper
    await func(reddit_instance)
  File "/mnt/secondary-ssd/Programming/Pycharm/basedcount_bot/basedcount_bot.py", line 83, in check_mail
    await most_based()
  File "/mnt/secondary-ssd/Programming/Pycharm/basedcount_bot/bot_commands.py", line 17, in most_based
    top_ten = await data_based.find().sort("count", -1).limit(10)
TypeError: object MotorCursor can't be used in 'await' expression
[2022-12-11 18:39:29,791] INFO [basedcount_bot.py.check_mail:47] Received message from is_fake_Account, /mostbased: /mostbased
[2022-12-11 18:39:29,795] CRITICAL [basedcount_bot.py.wrapper:26] Serious Exception
Traceback (most recent call last):
  File "/mnt/secondary-ssd/Programming/Pycharm/basedcount_bot/basedcount_bot.py", line 22, in wrapper
    await func(reddit_instance)
  File "/mnt/secondary-ssd/Programming/Pycharm/basedcount_bot/basedcount_bot.py", line 83, in check_mail
    await most_based()
  File "/mnt/secondary-ssd/Programming/Pycharm/basedcount_bot/bot_commands.py", line 17, in most_based
    top_ten = await data_based.find().sort("count", -1).limit(10)
TypeError: object MotorCursor can't be used in 'await' expression
[2022-12-11 18:39:29,903] INFO [basedcount_bot.py.check_mail:47] Received message from is_fake_Account, /mostbased: /mostbased
[2022-12-11 18:39:29,906] CRITICAL [basedcount_bot.py.wrapper:26] Serious Exception
Traceback (most recent call last):
  File "/mnt/secondary-ssd/Programming/Pycharm/basedcount_bot/basedcount_bot.py", line 22, in wrapper
    await func(reddit_instance)
  File "/mnt/secondary-ssd/Programming/Pycharm/basedcount_bot/basedcount_bot.py", line 83, in check_mail
    await most_based()
  File "/mnt/secondary-ssd/Programming/Pycharm/basedcount_bot/bot_commands.py", line 17, in most_based
    top_ten = await data_based.find().sort("count", -1).limit(10)
TypeError: object MotorCursor can't be used in 'await' expression
[2022-12-11 18:39:30,056] INFO [basedcount_bot.py.check_mail:47] Received message from is_fake_Account, /mostbased: /mostbased
[2022-12-11 18:39:30,059] CRITICAL [basedcount_bot.py.wrapper:26] Serious Exception
Traceback (most recent call last):
  File "/mnt/secondary-ssd/Programming/Pycharm/basedcount_bot/basedcount_bot.py", line 22, in wrapper
    await func(reddit_instance)
  File "/mnt/secondary-ssd/Programming/Pycharm/basedcount_bot/basedcount_bot.py", line 83, in check_mail
    await most_based()
  File "/mnt/secondary-ssd/Programming/Pycharm/basedcount_bot/bot_commands.py", line 17, in most_based
    top_ten = await data_based.find().sort("count", -1).limit(10)
TypeError: object MotorCursor can't be used in 'await' expression
[2022-12-11 18:39:30,173] INFO [basedcount_bot.py.check_mail:47] Received message from is_fake_Account, /mostbased: /mostbased
[2022-12-11 18:39:30,176] CRITICAL [basedcount_bot.py.wrapper:26] Serious Exception
Traceback (most recent call last):
  File "/mnt/secondary-ssd/Programming/Pycharm/basedcount_bot/basedcount_bot.py", line 22, in wrapper
    await func(reddit_instance)
  File "/mnt/secondary-ssd/Programming/Pycharm/basedcount_bot/basedcount_bot.py", line 83, in check_mail
    await most_based()
  File "/mnt/secondary-ssd/Programming/Pycharm/basedcount_bot/bot_commands.py", line 17, in most_based
    top_ten = await data_based.find().sort("count", -1).limit(10)
TypeError: object MotorCursor can't be used in 'await' expression
[2022-12-11 18:39:30,279] INFO [basedcount_bot.py.check_mail:47] Received message from is_fake_Account, /mostbased: /mostbased
[2022-12-11 18:39:30,282] CRITICAL [basedcount_bot.py.wrapper:26] Serious Exception
Traceback (most recent call last):
  File "/mnt/secondary-ssd/Programming/Pycharm/basedcount_bot/basedcount_bot.py", line 22, in wrapper
    await func(reddit_instance)
  File "/mnt/secondary-ssd/Programming/Pycharm/basedcount_bot/basedcount_bot.py", line 83, in check_mail
    await most_based()
  File "/mnt/secondary-ssd/Programming/Pycharm/basedcount_bot/bot_commands.py", line 17, in most_based
    top_ten = await data_based.find().sort("count", -1).limit(10)
TypeError: object MotorCursor can't be used in 'await' expression
[2022-12-11 18:39:30,415] INFO [basedcount_bot.py.check_mail:47] Received message from is_fake_Account, /mostbased: /mostbased
[2022-12-11 18:39:30,417] CRITICAL [basedcount_bot.py.wrapper:26] Serious Exception
Traceback (most recent call last):
  File "/mnt/secondary-ssd/Programming/Pycharm/basedcount_bot/basedcount_bot.py", line 22, in wrapper
    await func(reddit_instance)
  File "/mnt/secondary-ssd/Programming/Pycharm/basedcount_bot/basedcount_bot.py", line 83, in check_mail
    await most_based()
  File "/mnt/secondary-ssd/Programming/Pycharm/basedcount_bot/bot_commands.py", line 17, in most_based
    top_ten = await data_based.find().sort("count", -1).limit(10)
TypeError: object MotorCursor can't be used in 'await' expression
[2022-12-11 18:39:30,547] INFO [basedcount_bot.py.check_mail:47] Received message from is_fake_Account, /mostbased: /mostbased
[2022-12-11 18:39:30,550] CRITICAL [basedcount_bot.py.wrapper:26] Serious Exception
Traceback (most recent call last):
  File "/mnt/secondary-ssd/Programming/Pycharm/basedcount_bot/basedcount_bot.py", line 22, in wrapper
    await func(reddit_instance)
  File "/mnt/secondary-ssd/Programming/Pycharm/basedcount_bot/basedcount_bot.py", line 83, in check_mail
    await most_based()
  File "/mnt/secondary-ssd/Programming/Pycharm/basedcount_bot/bot_commands.py", line 17, in most_based
    top_ten = await data_based.find().sort("count", -1).limit(10)
TypeError: object MotorCursor can't be used in 'await' expression
[2022-12-11 18:39:30,663] INFO [basedcount_bot.py.read_comments:98] Logged into XUIDChecker Account.
[2022-12-11 18:39:30,720] INFO [basedcount_bot.py.check_mail:47] Received message from is_fake_Account, /mostbased: /mostbased
[2022-12-11 18:39:30,723] CRITICAL [basedcount_bot.py.wrapper:26] Serious Exception
Traceback (most recent call last):
  File "/mnt/secondary-ssd/Programming/Pycharm/basedcount_bot/basedcount_bot.py", line 22, in wrapper
    await func(reddit_instance)
  File "/mnt/secondary-ssd/Programming/Pycharm/basedcount_bot/basedcount_bot.py", line 83, in check_mail
    await most_based()
  File "/mnt/secondary-ssd/Programming/Pycharm/basedcount_bot/bot_commands.py", line 17, in most_based
    top_ten = await data_based.find().sort("count", -1).limit(10)
TypeError: object MotorCursor can't be used in 'await' expression
[2022-12-11 18:39:30,839] INFO [basedcount_bot.py.check_mail:47] Received message from is_fake_Account, /mostbased: /mostbased
[2022-12-11 18:39:30,842] CRITICAL [basedcount_bot.py.wrapper:26] Serious Exception
Traceback (most recent call last):
  File "/mnt/secondary-ssd/Programming/Pycharm/basedcount_bot/basedcount_bot.py", line 22, in wrapper
    await func(reddit_instance)
  File "/mnt/secondary-ssd/Programming/Pycharm/basedcount_bot/basedcount_bot.py", line 83, in check_mail
    await most_based()
  File "/mnt/secondary-ssd/Programming/Pycharm/basedcount_bot/bot_commands.py", line 17, in most_based
    top_ten = await data_based.find().sort("count", -1).limit(10)
TypeError: object MotorCursor can't be used in 'await' expression
[2022-12-11 18:39:30,968] INFO [basedcount_bot.py.check_mail:47] Received message from is_fake_Account, /mostbased: /mostbased
[2022-12-11 18:39:30,971] CRITICAL [basedcount_bot.py.wrapper:26] Serious Exception
Traceback (most recent call last):
  File "/mnt/secondary-ssd/Programming/Pycharm/basedcount_bot/basedcount_bot.py", line 22, in wrapper
    await func(reddit_instance)
  File "/mnt/secondary-ssd/Programming/Pycharm/basedcount_bot/basedcount_bot.py", line 83, in check_mail
    await most_based()
  File "/mnt/secondary-ssd/Programming/Pycharm/basedcount_bot/bot_commands.py", line 17, in most_based
    top_ten = await data_based.find().sort("count", -1).limit(10)
TypeError: object MotorCursor can't be used in 'await' expression
[2022-12-11 18:39:31,081] INFO [basedcount_bot.py.check_mail:47] Received message from is_fake_Account, /mostbased: /mostbased
[2022-12-11 18:39:31,084] CRITICAL [basedcount_bot.py.wrapper:26] Serious Exception
Traceback (most recent call last):
  File "/mnt/secondary-ssd/Programming/Pycharm/basedcount_bot/basedcount_bot.py", line 22, in wrapper
    await func(reddit_instance)
  File "/mnt/secondary-ssd/Programming/Pycharm/basedcount_bot/basedcount_bot.py", line 83, in check_mail
    await most_based()
  File "/mnt/secondary-ssd/Programming/Pycharm/basedcount_bot/bot_commands.py", line 17, in most_based
    top_ten = await data_based.find().sort("count", -1).limit(10)
TypeError: object MotorCursor can't be used in 'await' expression
[2022-12-11 18:39:31,199] INFO [basedcount_bot.py.check_mail:47] Received message from is_fake_Account, /mostbased: /mostbased
[2022-12-11 18:39:31,202] CRITICAL [basedcount_bot.py.wrapper:26] Serious Exception
Traceback (most recent call last):
  File "/mnt/secondary-ssd/Programming/Pycharm/basedcount_bot/basedcount_bot.py", line 22, in wrapper
    await func(reddit_instance)
  File "/mnt/secondary-ssd/Programming/Pycharm/basedcount_bot/basedcount_bot.py", line 83, in check_mail
    await most_based()
  File "/mnt/secondary-ssd/Programming/Pycharm/basedcount_bot/bot_commands.py", line 17, in most_based
    top_ten = await data_based.find().sort("count", -1).limit(10)
TypeError: object MotorCursor can't be used in 'await' expression
[2022-12-11 18:39:31,328] INFO [basedcount_bot.py.check_mail:47] Received message from is_fake_Account, /mostbased: /mostbased
[2022-12-11 18:39:31,331] CRITICAL [basedcount_bot.py.wrapper:26] Serious Exception
Traceback (most recent call last):
  File "/mnt/secondary-ssd/Programming/Pycharm/basedcount_bot/basedcount_bot.py", line 22, in wrapper
    await func(reddit_instance)
  File "/mnt/secondary-ssd/Programming/Pycharm/basedcount_bot/basedcount_bot.py", line 83, in check_mail
    await most_based()
  File "/mnt/secondary-ssd/Programming/Pycharm/basedcount_bot/bot_commands.py", line 17, in most_based
    top_ten = await data_based.find().sort("count", -1).limit(10)
TypeError: object MotorCursor can't be used in 'await' expression
[2022-12-11 18:39:31,442] INFO [basedcount_bot.py.check_mail:47] Received message from is_fake_Account, /mostbased: /mostbased
[2022-12-11 18:39:31,445] CRITICAL [basedcount_bot.py.wrapper:26] Serious Exception
Traceback (most recent call last):
  File "/mnt/secondary-ssd/Programming/Pycharm/basedcount_bot/basedcount_bot.py", line 22, in wrapper
    await func(reddit_instance)
  File "/mnt/secondary-ssd/Programming/Pycharm/basedcount_bot/basedcount_bot.py", line 83, in check_mail
    await most_based()
  File "/mnt/secondary-ssd/Programming/Pycharm/basedcount_bot/bot_commands.py", line 17, in most_based
    top_ten = await data_based.find().sort("count", -1).limit(10)
TypeError: object MotorCursor can't be used in 'await' expression
[2022-12-11 18:39:31,555] INFO [basedcount_bot.py.check_mail:47] Received message from is_fake_Account, /mostbased: /mostbased
[2022-12-11 18:39:31,559] CRITICAL [basedcount_bot.py.wrapper:26] Serious Exception
Traceback (most recent call last):
  File "/mnt/secondary-ssd/Programming/Pycharm/basedcount_bot/basedcount_bot.py", line 22, in wrapper
    await func(reddit_instance)
  File "/mnt/secondary-ssd/Programming/Pycharm/basedcount_bot/basedcount_bot.py", line 83, in check_mail
    await most_based()
  File "/mnt/secondary-ssd/Programming/Pycharm/basedcount_bot/bot_commands.py", line 17, in most_based
    top_ten = await data_based.find().sort("count", -1).limit(10)
TypeError: object MotorCursor can't be used in 'await' expression
[2022-12-11 18:39:31,656] INFO [basedcount_bot.py.check_mail:47] Received message from is_fake_Account, /mostbased: /mostbased
[2022-12-11 18:39:31,660] CRITICAL [basedcount_bot.py.wrapper:26] Serious Exception
Traceback (most recent call last):
  File "/mnt/secondary-ssd/Programming/Pycharm/basedcount_bot/basedcount_bot.py", line 22, in wrapper
    await func(reddit_instance)
  File "/mnt/secondary-ssd/Programming/Pycharm/basedcount_bot/basedcount_bot.py", line 83, in check_mail
    await most_based()
  File "/mnt/secondary-ssd/Programming/Pycharm/basedcount_bot/bot_commands.py", line 17, in most_based
    top_ten = await data_based.find().sort("count", -1).limit(10)
TypeError: object MotorCursor can't be used in 'await' expression
[2022-12-11 18:39:31,776] INFO [basedcount_bot.py.check_mail:47] Received message from is_fake_Account, /mostbased: /mostbased
[2022-12-11 18:39:31,779] CRITICAL [basedcount_bot.py.wrapper:26] Serious Exception
Traceback (most recent call last):
  File "/mnt/secondary-ssd/Programming/Pycharm/basedcount_bot/basedcount_bot.py", line 22, in wrapper
    await func(reddit_instance)
  File "/mnt/secondary-ssd/Programming/Pycharm/basedcount_bot/basedcount_bot.py", line 83, in check_mail
    await most_based()
  File "/mnt/secondary-ssd/Programming/Pycharm/basedcount_bot/bot_commands.py", line 17, in most_based
    top_ten = await data_based.find().sort("count", -1).limit(10)
TypeError: object MotorCursor can't be used in 'await' expression
[2022-12-11 18:39:31,974] INFO [basedcount_bot.py.check_mail:47] Received message from is_fake_Account, /mostbased: /mostbased
[2022-12-11 18:39:31,977] CRITICAL [basedcount_bot.py.wrapper:26] Serious Exception
Traceback (most recent call last):
  File "/mnt/secondary-ssd/Programming/Pycharm/basedcount_bot/basedcount_bot.py", line 22, in wrapper
    await func(reddit_instance)
  File "/mnt/secondary-ssd/Programming/Pycharm/basedcount_bot/basedcount_bot.py", line 83, in check_mail
    await most_based()
  File "/mnt/secondary-ssd/Programming/Pycharm/basedcount_bot/bot_commands.py", line 17, in most_based
    top_ten = await data_based.find().sort("count", -1).limit(10)
TypeError: object MotorCursor can't be used in 'await' expression
[2022-12-11 18:39:32,100] INFO [basedcount_bot.py.check_mail:47] Received message from is_fake_Account, /mostbased: /mostbased
[2022-12-11 18:39:32,103] CRITICAL [basedcount_bot.py.wrapper:26] Serious Exception
Traceback (most recent call last):
  File "/mnt/secondary-ssd/Programming/Pycharm/basedcount_bot/basedcount_bot.py", line 22, in wrapper
    await func(reddit_instance)
  File "/mnt/secondary-ssd/Programming/Pycharm/basedcount_bot/basedcount_bot.py", line 83, in check_mail
    await most_based()
  File "/mnt/secondary-ssd/Programming/Pycharm/basedcount_bot/bot_commands.py", line 17, in most_based
    top_ten = await data_based.find().sort("count", -1).limit(10)
TypeError: object MotorCursor can't be used in 'await' expression
[2022-12-11 18:39:32,225] INFO [basedcount_bot.py.check_mail:47] Received message from is_fake_Account, /mostbased: /mostbased
[2022-12-11 18:39:32,228] CRITICAL [basedcount_bot.py.wrapper:26] Serious Exception
Traceback (most recent call last):
  File "/mnt/secondary-ssd/Programming/Pycharm/basedcount_bot/basedcount_bot.py", line 22, in wrapper
    await func(reddit_instance)
  File "/mnt/secondary-ssd/Programming/Pycharm/basedcount_bot/basedcount_bot.py", line 83, in check_mail
    await most_based()
  File "/mnt/secondary-ssd/Programming/Pycharm/basedcount_bot/bot_commands.py", line 17, in most_based
    top_ten = await data_based.find().sort("count", -1).limit(10)
TypeError: object MotorCursor can't be used in 'await' expression
[2022-12-11 18:39:32,335] INFO [basedcount_bot.py.check_mail:47] Received message from is_fake_Account, /mostbased: /mostbased
[2022-12-11 18:39:32,338] CRITICAL [basedcount_bot.py.wrapper:26] Serious Exception
Traceback (most recent call last):
  File "/mnt/secondary-ssd/Programming/Pycharm/basedcount_bot/basedcount_bot.py", line 22, in wrapper
    await func(reddit_instance)
  File "/mnt/secondary-ssd/Programming/Pycharm/basedcount_bot/basedcount_bot.py", line 83, in check_mail
    await most_based()
  File "/mnt/secondary-ssd/Programming/Pycharm/basedcount_bot/bot_commands.py", line 17, in most_based
    top_ten = await data_based.find().sort("count", -1).limit(10)
TypeError: object MotorCursor can't be used in 'await' expression
[2022-12-11 18:39:32,513] INFO [basedcount_bot.py.check_mail:47] Received message from is_fake_Account, /mostbased: /mostbased
[2022-12-11 18:39:32,515] CRITICAL [basedcount_bot.py.wrapper:26] Serious Exception
Traceback (most recent call last):
  File "/mnt/secondary-ssd/Programming/Pycharm/basedcount_bot/basedcount_bot.py", line 22, in wrapper
    await func(reddit_instance)
  File "/mnt/secondary-ssd/Programming/Pycharm/basedcount_bot/basedcount_bot.py", line 83, in check_mail
    await most_based()
  File "/mnt/secondary-ssd/Programming/Pycharm/basedcount_bot/bot_commands.py", line 17, in most_based
    top_ten = await data_based.find().sort("count", -1).limit(10)
TypeError: object MotorCursor can't be used in 'await' expression
[2022-12-11 18:39:32,625] INFO [basedcount_bot.py.check_mail:47] Received message from is_fake_Account, /mostbased: /mostbased
[2022-12-11 18:39:32,628] CRITICAL [basedcount_bot.py.wrapper:26] Serious Exception
Traceback (most recent call last):
  File "/mnt/secondary-ssd/Programming/Pycharm/basedcount_bot/basedcount_bot.py", line 22, in wrapper
    await func(reddit_instance)
  File "/mnt/secondary-ssd/Programming/Pycharm/basedcount_bot/basedcount_bot.py", line 83, in check_mail
    await most_based()
  File "/mnt/secondary-ssd/Programming/Pycharm/basedcount_bot/bot_commands.py", line 17, in most_based
    top_ten = await data_based.find().sort("count", -1).limit(10)
TypeError: object MotorCursor can't be used in 'await' expression
[2022-12-11 18:39:32,664] INFO [basedcount_bot.py.read_comments:98] Logged into XUIDChecker Account.
[2022-12-11 18:39:32,744] INFO [basedcount_bot.py.check_mail:47] Received message from is_fake_Account, /mostbased: /mostbased
[2022-12-11 18:39:32,748] CRITICAL [basedcount_bot.py.wrapper:26] Serious Exception
Traceback (most recent call last):
  File "/mnt/secondary-ssd/Programming/Pycharm/basedcount_bot/basedcount_bot.py", line 22, in wrapper
    await func(reddit_instance)
  File "/mnt/secondary-ssd/Programming/Pycharm/basedcount_bot/basedcount_bot.py", line 83, in check_mail
    await most_based()
  File "/mnt/secondary-ssd/Programming/Pycharm/basedcount_bot/bot_commands.py", line 17, in most_based
    top_ten = await data_based.find().sort("count", -1).limit(10)
TypeError: object MotorCursor can't be used in 'await' expression
[2022-12-11 18:39:40,195] INFO [basedcount_bot.py.check_mail:47] Received message from is_fake_Account, /mostbased: /mostbased
[2022-12-11 18:39:47,924] INFO [basedcount_bot.py.check_mail:47] Received message from is_fake_Account, /mostbased: /mostbased
[2022-12-11 18:43:43,983] INFO [basedcount_bot.py.check_mail:47] Received message from is_fake_Account, /mostbased: /mostbased
[2022-12-11 18:45:39,977] ERROR [basedcount_bot.py.wrapper:24] AsyncPrawcoreException
Traceback (most recent call last):
  File "/mnt/secondary-ssd/Programming/Pycharm/basedcount_bot/venv/lib/python3.10/site-packages/asyncprawcore/requestor.py", line 64, in request
    return await self._http.request(
  File "/mnt/secondary-ssd/Programming/Pycharm/basedcount_bot/venv/lib/python3.10/site-packages/aiohttp/client.py", line 560, in _request
    await resp.start(conn)
  File "/mnt/secondary-ssd/Programming/Pycharm/basedcount_bot/venv/lib/python3.10/site-packages/aiohttp/client_reqrep.py", line 894, in start
    with self._timer:
  File "/mnt/secondary-ssd/Programming/Pycharm/basedcount_bot/venv/lib/python3.10/site-packages/aiohttp/helpers.py", line 720, in __exit__
    raise asyncio.TimeoutError from None
asyncio.exceptions.TimeoutError

During handling of the above exception, another exception occurred:

Traceback (most recent call last):
  File "/mnt/secondary-ssd/Programming/Pycharm/basedcount_bot/basedcount_bot.py", line 22, in wrapper
    await func(reddit_instance)
  File "/mnt/secondary-ssd/Programming/Pycharm/basedcount_bot/basedcount_bot.py", line 89, in read_comments
    @exception_wrapper
  File "/mnt/secondary-ssd/Programming/Pycharm/basedcount_bot/basedcount_bot.py", line 98, in read_comments
    main_logger.info(f"Logged into {await reddit_instance.user.me()} Account.")
  File "/mnt/secondary-ssd/Programming/Pycharm/basedcount_bot/venv/lib/python3.10/site-packages/asyncpraw/util/deprecate_args.py", line 51, in wrapped
    return await _wrapper(*args, **kwargs)
  File "/mnt/secondary-ssd/Programming/Pycharm/basedcount_bot/venv/lib/python3.10/site-packages/asyncpraw/models/user.py", line 169, in me
    user_data = await self._reddit.get(API_PATH["me"])
  File "/mnt/secondary-ssd/Programming/Pycharm/basedcount_bot/venv/lib/python3.10/site-packages/asyncpraw/util/deprecate_args.py", line 51, in wrapped
    return await _wrapper(*args, **kwargs)
  File "/mnt/secondary-ssd/Programming/Pycharm/basedcount_bot/venv/lib/python3.10/site-packages/asyncpraw/reddit.py", line 707, in get
    return await self._objectify_request(method="GET", params=params, path=path)
  File "/mnt/secondary-ssd/Programming/Pycharm/basedcount_bot/venv/lib/python3.10/site-packages/asyncpraw/reddit.py", line 815, in _objectify_request
    await self.request(
  File "/mnt/secondary-ssd/Programming/Pycharm/basedcount_bot/venv/lib/python3.10/site-packages/asyncpraw/util/deprecate_args.py", line 51, in wrapped
    return await _wrapper(*args, **kwargs)
  File "/mnt/secondary-ssd/Programming/Pycharm/basedcount_bot/venv/lib/python3.10/site-packages/asyncpraw/reddit.py", line 1032, in request
    return await self._core.request(
  File "/mnt/secondary-ssd/Programming/Pycharm/basedcount_bot/venv/lib/python3.10/site-packages/asyncprawcore/sessions.py", line 370, in request
    return await self._request_with_retries(
  File "/mnt/secondary-ssd/Programming/Pycharm/basedcount_bot/venv/lib/python3.10/site-packages/asyncprawcore/sessions.py", line 270, in _request_with_retries
    response, saved_exception = await self._make_request(
  File "/mnt/secondary-ssd/Programming/Pycharm/basedcount_bot/venv/lib/python3.10/site-packages/asyncprawcore/sessions.py", line 187, in _make_request
    response = await self._rate_limiter.call(
  File "/mnt/secondary-ssd/Programming/Pycharm/basedcount_bot/venv/lib/python3.10/site-packages/asyncprawcore/rate_limit.py", line 35, in call
    response = await request_function(*args, **kwargs)
  File "/mnt/secondary-ssd/Programming/Pycharm/basedcount_bot/venv/lib/python3.10/site-packages/asyncprawcore/requestor.py", line 68, in request
    raise RequestException(exc, args, kwargs)
asyncprawcore.exceptions.RequestException: error with request
[2022-12-11 18:45:40,235] INFO [basedcount_bot.py.read_comments:98] Logged into XUIDChecker Account.
[2022-12-11 18:47:04,272] INFO [basedcount_bot.py.read_comments:98] Logged into XUIDChecker Account.
[2022-12-11 18:48:27,460] INFO [basedcount_bot.py.read_comments:98] Logged into XUIDChecker Account.
[2022-12-11 18:48:29,463] INFO [basedcount_bot.py.read_comments:98] Logged into XUIDChecker Account.
[2022-12-11 18:48:31,474] INFO [basedcount_bot.py.read_comments:98] Logged into XUIDChecker Account.
[2022-12-11 18:48:33,479] INFO [basedcount_bot.py.read_comments:98] Logged into XUIDChecker Account.
[2022-12-11 18:48:35,486] INFO [basedcount_bot.py.read_comments:98] Logged into XUIDChecker Account.
[2022-12-11 18:48:37,494] INFO [basedcount_bot.py.read_comments:98] Logged into XUIDChecker Account.
[2022-12-11 18:48:37,622] INFO [basedcount_bot.py.check_mail:47] Received message from is_fake_Account, /mostbased: /mostbased
[2022-12-11 18:48:39,497] INFO [basedcount_bot.py.read_comments:98] Logged into XUIDChecker Account.
[2022-12-11 18:48:41,508] INFO [basedcount_bot.py.read_comments:98] Logged into XUIDChecker Account.
[2022-12-11 18:48:43,511] INFO [basedcount_bot.py.read_comments:98] Logged into XUIDChecker Account.
[2022-12-11 18:48:45,514] INFO [basedcount_bot.py.read_comments:98] Logged into XUIDChecker Account.
[2022-12-11 18:48:47,525] INFO [basedcount_bot.py.read_comments:98] Logged into XUIDChecker Account.
[2022-12-11 18:48:49,534] INFO [basedcount_bot.py.read_comments:98] Logged into XUIDChecker Account.
[2022-12-11 18:49:28,766] INFO [basedcount_bot.py.read_comments:97] Logged into XUIDChecker Account.
[2022-12-11 18:49:38,791] INFO [basedcount_bot.py.read_comments:97] Logged into XUIDChecker Account.
[2022-12-11 18:49:48,814] INFO [basedcount_bot.py.read_comments:97] Logged into XUIDChecker Account.
[2022-12-11 18:49:54,234] INFO [basedcount_bot.py.check_mail:47] Received message from is_fake_Account, /mostbased: /mostbased
[2022-12-11 18:49:58,826] INFO [basedcount_bot.py.read_comments:97] Logged into XUIDChecker Account.
[2022-12-11 18:50:08,832] INFO [basedcount_bot.py.read_comments:97] Logged into XUIDChecker Account.
[2022-12-11 18:50:18,844] INFO [basedcount_bot.py.read_comments:97] Logged into XUIDChecker Account.
[2022-12-11 18:50:28,852] INFO [basedcount_bot.py.read_comments:97] Logged into XUIDChecker Account.
[2022-12-11 18:50:38,857] INFO [basedcount_bot.py.read_comments:97] Logged into XUIDChecker Account.
[2022-12-11 18:50:48,862] INFO [basedcount_bot.py.read_comments:97] Logged into XUIDChecker Account.
[2022-12-11 18:50:58,867] INFO [basedcount_bot.py.read_comments:97] Logged into XUIDChecker Account.
[2022-12-11 18:51:08,873] INFO [basedcount_bot.py.read_comments:97] Logged into XUIDChecker Account.
[2022-12-11 18:51:18,879] INFO [basedcount_bot.py.read_comments:97] Logged into XUIDChecker Account.
[2022-12-11 18:51:28,881] INFO [basedcount_bot.py.read_comments:97] Logged into XUIDChecker Account.
[2022-12-11 18:51:38,882] INFO [basedcount_bot.py.read_comments:97] Logged into XUIDChecker Account.
